package gregicality.science.jei.multi.advance;

import gregicality.science.item.GAMetaBlocks;
import gregicality.science.item.GAReactorCasing;
import gregicality.science.item.GATransparentCasing;
import gregicality.science.jei.GAMultiblockShapeInfo;
import gregicality.science.machines.GAMetaTileEntities;
import gregtech.api.metatileentity.multiblock.MultiblockControllerBase;
import gregtech.common.blocks.MetaBlocks;
import gregtech.common.metatileentities.MetaTileEntities;
import gregtech.integration.jei.multiblock.MultiblockInfoPage;
import gregtech.integration.jei.multiblock.MultiblockShapeInfo;
import net.minecraft.client.resources.I18n;
import net.minecraft.init.Blocks;
import net.minecraft.util.EnumFacing;

import java.util.Collections;
import java.util.List;

import static gregtech.api.unification.material.Materials.Naquadria;

public class HyperReactor3Info extends MultiblockInfoPage {
    @Override
    public MultiblockControllerBase getController() {
        return GAMetaTileEntities.HYPER_REACTOR_III;
    }

    @Override
    public List<MultiblockShapeInfo> getMatchingShapes() {
        GAMultiblockShapeInfo.Builder builder = GAMultiblockShapeInfo.builder();
           builder.aisle("###########","###########","###########","###########","###########", "###########", "###########", "###########", "####CCC####", "###CCMCC###", "###CCSfC###", "###CCCCC###", "####CCC####", "###########", "###########", "###########")
                  .aisle("###########","###########","###########","###########","###########", "###########", "###########", "###CCCCC###", "##CC###CC##", "##C#####C##", "##C#####C##", "##C#####C##", "##CC###CC##", "###CCCCC###", "###########", "###########")
                  .aisle("##F#####F##","##F#####F##","##F#####F##","##F#####F##","##F#####F##", "##F#####F##", "##FCCCCCF##", "##C#####C##", "#C#######C#", "#C#######C#", "#C#######C#", "#C#######C#", "#C#######C#", "##C#####C##", "###CCCCC###", "###########")
                  .aisle("###F###F###","###F###F###","###F###F###","###F###F###","###F###F###", "###FCCCF###", "##CC###CC##", "#C#######C#", "#C#######C#", "C#########C", "C####H####C", "C#########C", "#C#######C#", "#C#######C#", "##CC###CC##", "####CCC####")
                  .aisle("###########","###########","###########","###########","###########", "###CCCCC###", "##C#####C##", "#C#######C#", "C#########C", "G####H####G", "G###HHH###G", "G####H####G", "C#########C", "#C#######C#", "##C#####C##", "###CCCCC###")
                  .aisle("###########","###########","###########","###########","###########", "###CCCCC###", "##C#####C##", "#C#######C#", "C####H####C", "G###HHH###G", "G##HHHHH##G", "G###HHH###G", "C####H####C", "#C#######C#", "##C#####C##", "###CCCCC###")
                  .aisle("###########","###########","###########","###########","###########", "###CCCCC###", "##C#####C##", "#C#######C#", "C#########C", "G####H####G", "G###HHH###G", "G####H####G", "C#########C", "#C#######C#", "##C#####C##", "###CCCCC###")
                  .aisle("###F###F###","###F###F###","###F###F###","###F###F###","###F###F###", "###FCCCF###", "##CC###CC##", "#C#######C#", "#C#######C#", "C#########C", "C####H####C", "C#########C", "#C#######C#", "#C#######C#", "##CC###CC##", "####CCC####")
                  .aisle("##F#####F##","##F#####F##","##F#####F##","##F#####F##","##F#####F##", "##F#####F##", "##FCCCCCF##", "##C#####C##", "#C#######C#", "#C#######C#", "#C#######C#", "#C#######C#", "#C#######C#", "##C#####C##", "###CCCCC###", "###########")
                  .aisle("###########","###########","###########","###########","###########", "###########", "###########", "###CCCCC###", "##CC###CC##", "##C#####C##", "##C#####C##", "##C#####C##", "##CC###CC##", "###CCCCC###", "###########", "###########")
                  .aisle("###########","###########","###########","###########","###########", "###########", "###########", "###########", "####CCC####", "###CCCCC###", "###CCECC###", "###CCCCC###", "####CCC####", "###########", "###########", "###########")
                  .where('S', GAMetaTileEntities.HYPER_REACTOR_III, EnumFacing.NORTH)
                  .where('M', maintenanceIfEnabled(GAMetaBlocks.REACTOR_CASING.getState(GAReactorCasing.CasingType.HYPER_CASING_2)), EnumFacing.NORTH)
                  .where('C', GAMetaBlocks.REACTOR_CASING.getState(GAReactorCasing.CasingType.HYPER_CASING_2))
                  .where('f', MetaTileEntities.FLUID_IMPORT_HATCH[4], EnumFacing.NORTH)
                  .where('E', MetaTileEntities.ENERGY_OUTPUT_HATCH[8], EnumFacing.SOUTH)
                  .where('G', GAMetaBlocks.TRANSPARENT_CASING.getState(GATransparentCasing.CasingType.OSMIRIDIUM_GLASS))
                  .where('H', GAMetaBlocks.REACTOR_CASING.getState(GAReactorCasing.CasingType.HYPER_CORE_3))
                  .where('#', Blocks.AIR.getDefaultState())
                  .where('F', MetaBlocks.FRAMES.get(Naquadria).getDefaultState());
        return Collections.singletonList(builder.build());
    }

    @Override
    public String[] getDescription() {
        return new String[]{I18n.format("gtadditions.multiblock.hyper_reactor.description")};
    }

    @Override
    public float getDefaultZoom() {
        return 0.3f;
    }
}
